<?xml version="1.0"?>
<robot name="human_model">
    <link name="human_base" />
	<joint name="world_to_ref" type="fixed">
		<origin rpy="0 0 -1.570796 " xyz="0 0 0"/>
		<parent link="human_base"/>
		<child link="ref1"/>
    </joint>

    <link name="ref1" />
	<joint name="ref1_to_ref" type="fixed">
		<origin rpy="1.570796 0 0" xyz="0 0 0"/>
		<parent link="ref1"/>
		<child link="ref"/>
    </joint>

    <link name="ref" />

	<joint name="ref_to_hip_z" type="continuous">
		<axis xyz="0 0 1"/>
		<origin rpy="0 0 0 " xyz="0 0 0"/>
		<parent link="ref"/>
		<child link="hip_z"/>
	</joint>

    <link name="hip_z"/>

	<joint name="hip_z_to_hip_x" type="continuous">
		<axis xyz="1 0 0"/>
		<origin rpy="0 0 0 " xyz="0 0 0"/>
		<parent link="hip_z"/>
		<child link="hip_x"/>
    </joint>

    <link name="hip_x"/>

	<joint name="hip_x_to_hip_y" type="continuous">
		<axis xyz="0 1 0"/>
		<origin rpy="0 0 0 " xyz="0 0 0"/>
		<parent link="hip_x"/>
        <child link="hip_y"/>
    </joint>

    <link name="hip_y"/>

    <joint name="hip_y_to_hip" type="fixed">
		<origin rpy="0 0 0" xyz="0 0 0"/>
		<parent link="hip_y"/>
		<child link="hip"/>
    </joint>


	<link name="hip">
		<visual>
			<geometry>
				<sphere radius="0.03"/>
			</geometry>
			<origin xyz="0 0 0"/>
		</visual>
    </link>

	<link name="spine">
		<visual>
			<geometry>
				<cylinder length="0.05" radius="0.02"/>
			</geometry>
			<origin xyz="0 0 0"/>
		</visual>
    </link>

	<joint name="hip_to_spine" type="fixed">
		<origin rpy="0 0 0 " xyz="0.0 0.044134024 -0.066201036"/>
		<parent link="hip"/>
		<child link="spine"/>
    </joint>

    <link name="spine1_z"/>

	<joint name="spine_to_spine1_z" type="continuous">
		<axis xyz="0 0 1"/>
		<origin rpy="0 0 0 " xyz="0 0 0"/>
		<parent link="spine"/>
		<child link="spine1_z"/>
	</joint>

    <link name="spine1_x"/>

	<joint name="spine1_z_to_spine1_x" type="continuous">
		<axis xyz="1 0 0"/>
		<origin rpy="0 0 0 " xyz="0 0 0"/>
		<parent link="spine1_z"/>
		<child link="spine1_x"/>
    </joint>

    <link name="spine1_y"/>

	<joint name="spine1_x_to_spine1_y" type="continuous">
		<axis xyz="0 1 0"/>
		<origin rpy="0 0 0 " xyz="0 0 0"/>
		<parent link="spine1_x"/>
		<child link="spine1_y"/>
    </joint>

    <link name="spine1">
		<visual>
			<geometry>
				<cylinder length="0.05" radius="0.02"/>
			</geometry>
			<origin rpy="0 0 0" xyz="0 0 0"/>
		</visual>
	</link>

	<joint name="spine1_y_to_spine1" type="fixed">
		<origin rpy="0 0 0 " xyz="0.0 0.01532763 -0.086927182"/>
		<parent link="spine1_y"/>
		<child link="spine1"/>
    </joint>




    <link name="spine2_z"/>

	<joint name="spine1_to_spine2_z" type="continuous">
		<axis xyz="0 0 1"/>
		<origin rpy="0 0 0 " xyz="0 0 0"/>
		<parent link="spine1"/>
		<child link="spine2_z"/>
	</joint>

    <link name="spine2_x"/>

	<joint name="spine2_z_to_spine2_x" type="continuous">
		<axis xyz="1 0 0"/>
		<origin rpy="0 0 0 " xyz="0 0 0"/>
		<parent link="spine2_z"/>
		<child link="spine2_x"/>
    </joint>

    <link name="spine2_y"/>

	<joint name="spine2_x_to_spine2_y" type="continuous">
		<axis xyz="0 1 0"/>
		<origin rpy="0 0 0 " xyz="0 0 0"/>
		<parent link="spine2_x"/>
		<child link="spine2_y"/>
    </joint>

    <link name="spine2">
		<visual>
			<geometry>
				<cylinder length="0.05" radius="0.02"/>
			</geometry>
			<origin rpy="0 0 0" xyz="0 0 0"/>
		</visual>
	</link>

	<joint name="spine2_y_to_spine2" type="fixed">
		<origin rpy="0 0 0 " xyz="0.0 0.007693152 -0.08793226"/>
		<parent link="spine2_y"/>
		<child link="spine2"/>
    </joint>




    <link name="spine3_z"/>

	<joint name="spine2_to_spine3_z" type="continuous">
		<axis xyz="0 0 1"/>
		<origin rpy="0 0 0 " xyz="0 0 0"/>
		<parent link="spine2"/>
		<child link="spine3_z"/>
	</joint>

    <link name="spine3_x"/>

	<joint name="spine3_z_to_spine3_x" type="continuous">
		<axis xyz="1 0 0"/>
		<origin rpy="0 0 0 " xyz="0 0 0"/>
		<parent link="spine3_z"/>
		<child link="spine3_x"/>
    </joint>

    <link name="spine3_y"/>

	<joint name="spine3_x_to_spine3_y" type="continuous">
		<axis xyz="0 1 0"/>
		<origin rpy="0 0 0 " xyz="0 0 0"/>
		<parent link="spine3_x"/>
		<child link="spine3_y"/>
    </joint>

    <link name="spine3">
		<visual>
			<geometry>
				<cylinder length="0.05" radius="0.02"/>
			</geometry>
			<origin rpy="0 0 0" xyz="0 0 0"/>
		</visual>
	</link>

	<joint name="spine3_y_to_spine3" type="fixed">
		<origin rpy="0 0 0 " xyz="0.0 0.0 -0.088268302"/>
		<parent link="spine3_y"/>
		<child link="spine3"/>
    </joint>




    <link name="neck_z"/>

	<joint name="spine3_to_neck_z" type="continuous">
		<axis xyz="0 0 1"/>
		<origin rpy="0 0 0 " xyz="0 0 0"/>
		<parent link="spine3"/>
		<child link="neck_z"/>
	</joint>

    <link name="neck_x"/>

	<joint name="neck_z_to_neck_x" type="continuous">
		<axis xyz="1 0 0"/>
		<origin rpy="0 0 0 " xyz="0 0 0"/>
		<parent link="neck_z"/>
		<child link="neck_x"/>
    </joint>

    <link name="neck_y"/>

	<joint name="neck_x_to_neck_y" type="continuous">
		<axis xyz="0 1 0"/>
		<origin rpy="0 0 0 " xyz="0 0 0"/>
		<parent link="neck_x"/>
		<child link="neck_y"/>
    </joint>

    <link name="neck">
		<visual>
			<geometry>
				<cylinder length="0.05" radius="0.02"/>
			</geometry>
			<origin rpy="0 0 0" xyz="0 0 0"/>
		</visual>
	</link>

	<joint name="neck_y_to_neck" type="fixed">
		<origin rpy="0 0 0 " xyz="0.0 -0.034628 -0.242399"/>
		<parent link="neck_y"/>
		<child link="neck"/>
    </joint>







    <link name="rShoulder">
		<visual>
			<geometry>
				<sphere radius="0.03"/>
			</geometry>
			<origin rpy="0 0 0" xyz="0 0 0"/>
		</visual>
	</link>

	<joint name="spine3_y_to_rShoulder" type="fixed">
		<origin rpy="0 0 0 " xyz="0.0297086274 -0.049514252 -0.1604268826"/>
		<parent link="neck_y"/>
		<child link="rShoulder"/>
    </joint>






    <link name="rArm_z"/>

	<joint name="rShoulder_to_rArm_z" type="continuous">
		<axis xyz="0 0 1"/>
		<origin rpy="0 0 0 " xyz="0 0 0"/>
		<parent link="rShoulder"/>
		<child link="rArm_z"/>
	</joint>

    <link name="rArm_x"/>

	<joint name="rArm_z_to_rArm_x" type="continuous">
		<axis xyz="1 0 0"/>
		<origin rpy="0 0 0 " xyz="0 0 0"/>
		<parent link="rArm_z"/>
		<child link="rArm_x"/>
    </joint>

    <link name="rArm_y"/>

	<joint name="rArm_x_to_rArm_y" type="continuous">
		<axis xyz="0 1 0"/>
		<origin rpy="0 0 0 " xyz="0 0 0"/>
		<parent link="rArm_x"/>
		<child link="rArm_y"/>
    </joint>

    <link name="rArm">
		<visual>
			<geometry>
				<sphere radius="0.03"/>
			</geometry>
			<origin rpy="0 0 0" xyz="0 0 0"/>
		</visual>
	</link>

	<joint name="rArm_y_to_rArm" type="fixed">
		<origin rpy="0 0 0 " xyz="0.17553172 0.0 0.0"/>
		<parent link="rArm_y"/>
		<child link="rArm"/>
    </joint>



    <link name="rForeArm_z"/>

	<joint name="rArm_to_rForeArm_z" type="continuous">
		<axis xyz="0 0 1"/>
		<origin rpy="0 0 0 " xyz="0 0 0"/>
		<parent link="rArm"/>
		<child link="rForeArm_z"/>
	</joint>

    <link name="rForeArm_x"/>

	<joint name="rForeArm_z_to_rForeArm_x" type="continuous">
		<axis xyz="1 0 0"/>
		<origin rpy="0 0 0 " xyz="0 0 0"/>
		<parent link="rForeArm_z"/>
		<child link="rForeArm_x"/>
    </joint>

    <link name="rForeArm_y"/>

	<joint name="rForeArm_x_to_rForeArm_y" type="continuous">
		<axis xyz="0 1 0"/>
		<origin rpy="0 0 0 " xyz="0 0 0"/>
		<parent link="rForeArm_x"/>
		<child link="rForeArm_y"/>
    </joint>

    <link name="rForeArm">
		<visual>
			<geometry>
				<sphere radius="0.03"/>
			</geometry>
			<origin rpy="0 0 0" xyz="0 0 0"/>
		</visual>
	</link>

	<joint name="rForeArm_y_to_rForeArm" type="fixed">
		<origin rpy="0 0 0 " xyz="0.26626185 0.0 5.08e-08"/>
		<parent link="rForeArm_y"/>
		<child link="rForeArm"/>
    </joint>




    <link name="rWrist_z"/>

	<joint name="rForeArm_to_rWrist_z" type="continuous">
		<axis xyz="0 0 1"/>
		<origin rpy="0 0 0 " xyz="0 0 0"/>
		<parent link="rForeArm"/>
		<child link="rWrist_z"/>
	</joint>

    <link name="rWrist_x"/>

	<joint name="rWrist_z_to_rWrist_x" type="continuous">
		<axis xyz="1 0 0"/>
		<origin rpy="0 0 0 " xyz="0 0 0"/>
		<parent link="rWrist_z"/>
		<child link="rWrist_x"/>
    </joint>

    <link name="rWrist_y"/>

	<joint name="rWrist_x_to_rWrist_y" type="continuous">
		<axis xyz="0 1 0"/>
		<origin rpy="0 0 0 " xyz="0 0 0"/>
		<parent link="rWrist_x"/>
		<child link="rWrist_y"/>
    </joint>

    <link name="rWrist">
		<visual>
			<geometry>
				<sphere radius="0.03"/>
			</geometry>
			<origin rpy="0 0 0" xyz="0 0 0"/>
		</visual>
	</link>

	<joint name="rWrist_y_to_rWrist" type="fixed">
		<origin rpy="0 0 0 " xyz="0.227727002 0.0 0.0"/>
		<parent link="rWrist_y"/>
		<child link="rWrist"/>
    </joint>


    <link name="rHand_z"/>

  	<joint name="rWrist_to_rHand_z" type="continuous">
      <axis xyz="0 0 1"/>
  		<origin rpy="0 0 0 " xyz="0.0 0.0 0.0"/>
  		<parent link="rWrist"/>
  		<child link="rHand_z"/>
    </joint>

    <link name="rHand_x"/>

  	<joint name="rHand_z_to_rHand_x" type="continuous">
  		<axis xyz="1 0 0"/>
  		<origin rpy="0 0 0 " xyz="0 0 0"/>
  		<parent link="rHand_z"/>
  		<child link="rHand_x"/>
      </joint>

      <link name="rHand_y"/>

  	<joint name="rHand_x_to_rHand_y" type="continuous">
  		<axis xyz="0 1 0"/>
  		<origin rpy="0 0 0 " xyz="0 0 0"/>
  		<parent link="rHand_x"/>
  		<child link="rHand_y"/>
      </joint>

      <link name="rHand">
  		<visual>
  			<geometry>
  				<box size="0.08 0.08 0.02"/>
  			</geometry>
  			<origin rpy="0 0 0" xyz="0 0 0"/>
  		</visual>
  	</link>

  	<joint name="rHand_y_to_rHand" type="fixed">
  		<origin rpy="0 0 0 " xyz="0.06377813 0.0 0.0"/>
  		<parent link="rHand_y"/>
  		<child link="rHand"/>
    </joint>


    <link name="lShoulder">
		<visual>
			<geometry>
				<sphere radius="0.03"/>
			</geometry>
			<origin rpy="0 0 0" xyz="0 0 0"/>
		</visual>
	</link>

	<joint name="spine3_y_to_lShoulder" type="fixed">
		<origin rpy="0 0 0 " xyz="-0.029708602 -0.049514252 -0.1604268826"/>
		<parent link="neck_y"/>
		<child link="lShoulder"/>
    </joint>






    <link name="lArm_z"/>

	<joint name="lShoulder_to_lArm_z" type="continuous">
		<axis xyz="0 0 1"/>
		<origin rpy="0 0 0 " xyz="0 0 0"/>
		<parent link="lShoulder"/>
		<child link="lArm_z"/>
	</joint>

    <link name="lArm_x"/>

	<joint name="lArm_z_to_lArm_x" type="continuous">
		<axis xyz="1 0 0"/>
		<origin rpy="0 0 0 " xyz="0 0 0"/>
		<parent link="lArm_z"/>
		<child link="lArm_x"/>
    </joint>

    <link name="lArm_y"/>

	<joint name="lArm_x_to_lArm_y" type="continuous">
		<axis xyz="0 1 0"/>
		<origin rpy="0 0 0 " xyz="0 0 0"/>
		<parent link="lArm_x"/>
		<child link="lArm_y"/>
    </joint>

    <link name="lArm">
		<visual>
			<geometry>
				<sphere radius="0.03"/>
			</geometry>
			<origin rpy="0 0 0" xyz="0 0 0"/>
		</visual>
	</link>

	<joint name="lArm_y_to_lArm" type="fixed">
		<!--origin rpy="0 0 0 " xyz="-0.1475531466 0.0 0.0"/-->
		<origin rpy="0 0 0 " xyz="-0.17553172 0.0 0.0"/>
		<parent link="lArm_y"/>
		<child link="lArm"/>
    </joint>



    <link name="lForeArm_z"/>

	<joint name="lArm_to_lForeArm_z" type="continuous">
		<axis xyz="0 0 1"/>
		<origin rpy="0 0 0 " xyz="0 0 0"/>
		<parent link="lArm"/>
		<child link="lForeArm_z"/>
	</joint>

    <link name="lForeArm_x"/>

	<joint name="lForeArm_z_to_lForeArm_x" type="continuous">
		<axis xyz="1 0 0"/>
		<origin rpy="0 0 0 " xyz="0 0 0"/>
		<parent link="lForeArm_z"/>
		<child link="lForeArm_x"/>
    </joint>

    <link name="lForeArm_y"/>

	<joint name="lForeArm_x_to_lForeArm_y" type="continuous">
		<axis xyz="0 1 0"/>
		<origin rpy="0 0 0 " xyz="0 0 0"/>
		<parent link="lForeArm_x"/>
		<child link="lForeArm_y"/>
    </joint>

    <link name="lForeArm">
		<visual>
			<geometry>
				<sphere radius="0.03"/>
			</geometry>
			<origin rpy="0 0 0" xyz="0 0 0"/>
		</visual>
	</link>

	<joint name="lForeArm_y_to_lForeArm" type="fixed">
		<origin rpy="0 0 0 " xyz="-0.26626185 0.0 -5.08e-08"/>
		<parent link="lForeArm_y"/>
		<child link="lForeArm"/>
    </joint>




  <link name="lWrist_z"/>

	<joint name="lForeArm_to_lWrist_z" type="continuous">
		<axis xyz="0 0 1"/>
		<origin rpy="0 0 0 " xyz="0 0 0"/>
		<parent link="lForeArm"/>
		<child link="lWrist_z"/>
	</joint>

  <link name="lWrist_x"/>

	<joint name="lWrist_z_to_lWrist_x" type="continuous">
		<axis xyz="1 0 0"/>
		<origin rpy="0 0 0 " xyz="0 0 0"/>
		<parent link="lWrist_z"/>
		<child link="lWrist_x"/>
    </joint>

    <link name="lWrist_y"/>

	<joint name="lWrist_x_to_lWrist_y" type="continuous">
		<axis xyz="0 1 0"/>
		<origin rpy="0 0 0 " xyz="0 0 0"/>
		<parent link="lWrist_x"/>
		<child link="lWrist_y"/>
    </joint>

    <link name="lWrist">
		<visual>
			<geometry>
				<sphere radius="0.03"/>
			</geometry>
			<origin rpy="0 0 0" xyz="0 0 0"/>
		</visual>
	</link>

  <joint name="lWrist_y_to_lWrist" type="fixed">
    <origin rpy="0 0 0 " xyz="-0.227727002 0.0 0.0"/>
    <parent link="lWrist_y"/>
    <child link="lWrist"/>
  </joint>


  <link name="lHand_z"/>

	<joint name="lWrist_to_lHand_z" type="continuous">
    <axis xyz="0 0 1"/>
		<origin rpy="0 0 0 " xyz="0.0 0.0 0.0"/>
		<parent link="lWrist"/>
		<child link="lHand_z"/>
  </joint>

    <link name="lHand_x"/>

	<joint name="lHand_z_to_lHand_x" type="continuous">
		<axis xyz="1 0 0"/>
		<origin rpy="0 0 0 " xyz="0 0 0"/>
		<parent link="lHand_z"/>
		<child link="lHand_x"/>
    </joint>

    <link name="lHand_y"/>

	<joint name="lHand_x_to_lHand_y" type="continuous">
		<axis xyz="0 1 0"/>
		<origin rpy="0 0 0 " xyz="0 0 0"/>
		<parent link="lHand_x"/>
		<child link="lHand_y"/>
    </joint>

    <link name="lHand">
		<visual>
			<geometry>
  				<box size="0.08 0.08 0.02"/>
			</geometry>
			<origin rpy="0 0 0" xyz="0 0 0"/>
		</visual>
	</link>

	<joint name="lHand_y_to_lHand" type="fixed">
		<origin rpy="0 0 0 " xyz="-0.06377813 0.0 0.0"/>
		<parent link="lHand_y"/>
		<child link="lHand"/>
  </joint>
</robot>
